INFO     src.api.package_route_api:package_route_api.py:42 Sending GET request to http://localhost:5000/packages/non-existent-package-id-123/status
ERROR    src.api.package_route_api:package_route_api.py:49 Error getting status for package ID non-existent-package-id-123: HTTPConnectionPool(host='localhost', port=5000): Max retries exceeded with url: /packages/non-existent-package-id-123/status (Caused by NewConnectionError('<urllib3.connection.HTTPConnection object at 0x7ff55b8c3fd0>: Failed to establish a new connection: [Errno 111] Connection refused'))